Workbook

Sheet run_notes
A1: Plan for Tuesday 2025-06-09
A2: Go to UNM, set out bucket of water to equilibrate to room temp
A3: Pack at UNM
B4: four clean water jugs
B5: two white buckets
B6: pump + tubing
B7: sharpie
B8: parafilm
B9: rubber bands
B10: field bag
B11: gloves?
A12: Go to sites and collect water as normal
A13: Take it back to campus
A14: Put jugs in buckets of room temp water (for how long?)
A15: Make remaining calibration standard and five QCs
A16: Make matrix spikes of each well (not filtered)
B17: 10 mg/L (times 4)
B18: 5 mg/L (times 4)
B19: 2 mg/L (times 4)
B20: 1 mg/L (times 4)
B21: 0.5 mg/L (times 4)
A22: Put in buckets of room temp water to equilibrate (for how long?)
A23: Procedure for NPOC analysis:
B24: Rinse the filter with the standard amount (20 mL?)
B25: Filter ~ 20 mL of sample into the vial
B26: Not acidifying!
A27: Procedure for filter rinse test:
B28: CHECK IF THERE ARE ENOUGH FILTER HOLDERS
B29: Have nanopure in a beaker
B30: Draw up ~ 50 mL of sample with a clean syringe
B31: Attach filter holder + filter
B32: Push through 5 mL of sample into vial 1, then 5 mL of sample into vial 2, etc.
B33: Repeat the above step with four filter holders + filters for a total of 20 mL per vial
B34: Repeat the above four steps with another syringe-full of 50 mL of nanopure, reusing the same filters

Sheet raw_data
A1: [Header]
A2: System | B2: TOC-L
A3: S/W Version | B3: 1
A4: User
A5: Date/Time | B5: 45819.533
A7: [System]
A8: Instrument Options | B8: TOC/ASI/IC Unit/TN/
A10: [Data]
A11: Type | B11: Anal. | C11: Sample Name | D11: Sample ID | E11: Date / Time | F11: Spl. No. | G11: Inj. No. | H11: Analysis(Inj.) | I11: Area | J11: Mean Area | K11: Conc. | L11: SD Area | M11: CV Area | N11: Vial | O11: Excluded | P11: Inj. Vol. | Q11: Auto. Dil.
A12: Unknown | B12: NPOC | C12: 0position | D12: Untitled | E12: 45818.756 | F12: 1 | G12: 1 | H12: NPOC | I12: 0.8239 | J12: 0.8424 | K12: 0 | L12: 0.02616 | M12: 3.11 | N12: 0 | O12: 0 | P12: 100 | Q12: 1
A13: Unknown | B13: NPOC | C13: 0position | D13: Untitled | E13: 45818.757 | F13: 1 | G13: 2 | H13: NPOC | I13: 0.8609 | J13: 0.8424 | K13: 0 | L13: 0.02616 | M13: 3.11 | N13: 0 | O13: 0 | P13: 100 | Q13: 1
A14: Unknown | B14: NPOC | C14: nanopure | D14: Untitled | E14: 45818.764 | F14: 1 | G14: 1 | H14: NPOC | I14: 0.4395 | J14: 0.4632 | K14: 0 | L14: 0.03345 | M14: 7.22 | N14: 1 | O14: 0 | P14: 100 | Q14: 1
A15: Unknown | B15: NPOC | C15: nanopure | D15: Untitled | E15: 45818.765 | F15: 1 | G15: 2 | H15: NPOC | I15: 0.4868 | J15: 0.4632 | K15: 0 | L15: 0.03345 | M15: 7.22 | N15: 1 | O15: 0 | P15: 100 | Q15: 1
A16: Standard | B16: NPOC | C16: NPOC_CAL | D16: NPOC_CAL | E16: 45818.774 | F16: 1 | G16: 1 | H16: NPOC | I16: 138 | J16: 137.3 | K16: 20 | L16: 0.9899 | M16: 0.72 | N16: 2 | O16: 0 | P16: 100 | Q16: 1
A17: Standard | B17: NPOC | C17: NPOC_CAL | D17: NPOC_CAL | E17: 45818.776 | F17: 1 | G17: 2 | H17: NPOC | I17: 136.6 | J17: 137.3 | K17: 20 | L17: 0.9899 | M17: 0.72 | N17: 2 | O17: 0 | P17: 100 | Q17: 1
A18: Standard | B18: NPOC | C18: NPOC_CAL | D18: NPOC_CAL | E18: 45818.784 | F18: 2 | G18: 1 | H18: NPOC | I18: 69.53 | J18: 69.06 | K18: 10 | L18: 0.6576 | M18: 0.95 | N18: 3 | O18: 0 | P18: 100 | Q18: 1
A19: Standard | B19: NPOC | C19: NPOC_CAL | D19: NPOC_CAL | E19: 45818.786 | F19: 2 | G19: 2 | H19: NPOC | I19: 68.6 | J19: 69.06 | K19: 10 | L19: 0.6576 | M19: 0.95 | N19: 3 | O19: 0 | P19: 100 | Q19: 1
A20: Standard | B20: NPOC | C20: NPOC_CAL | D20: NPOC_CAL | E20: 45818.794 | F20: 3 | G20: 1 | H20: NPOC | I20: 35.56 | J20: 34.2 | K20: 5 | L20: 0.2051 | M20: 0.6 | N20: 4 | O20: 1 | P20: 100 | Q20: 1
A21: Standard | B21: NPOC | C21: NPOC_CAL | D21: NPOC_CAL | E21: 45818.796 | F21: 3 | G21: 2 | H21: NPOC | I21: 34.35 | J21: 34.2 | K21: 5 | L21: 0.2051 | M21: 0.6 | N21: 4 | O21: 0 | P21: 100 | Q21: 1
A22: Standard | B22: NPOC | C22: NPOC_CAL | D22: NPOC_CAL | E22: 45818.798 | F22: 3 | G22: 3 | H22: NPOC | I22: 34.06 | J22: 34.2 | K22: 5 | L22: 0.2051 | M22: 0.6 | N22: 4 | O22: 0 | P22: 100 | Q22: 1
A23: Standard | B23: NPOC | C23: NPOC_CAL | D23: NPOC_CAL | E23: 45818.805 | F23: 4 | G23: 1 | H23: NPOC | I23: 14.35 | J23: 14.19 | K23: 2 | L23: 0.2333 | M23: 1.65 | N23: 5 | O23: 0 | P23: 100 | Q23: 1
... A206: Unknown | B206: NPOC | C206: 0position | D206: Untitled | E206: 45819.528 | F206: 1 | G206: 3 | H206: NPOC | I206: 0.9441 | J206: 0.8876 | K206: 0 | L206: 0.07997 | M206: 9.01 | N206: 0 | O206: 0 | P206: 100 | Q206: 1

Sheet working_data
A1: Sample Name | B1: Analysis(Inj.) | C1: Mean Area | D1: Conc. | E1: Vial
A2: 0position | B2: NPOC | C2: 0.8424 | D2: 0 | E2: 0
A3: nanopure | B3: NPOC | C3: 0.4632 | D3: 0 | E3: 1
A4: NPOC_CAL | B4: NPOC | C4: 137.3 | D4: 20 | E4: 2
A5: NPOC_CAL | B5: NPOC | C5: 69.06 | D5: 10 | E5: 3
A6: NPOC_CAL | B6: NPOC | C6: 34.2 | D6: 5 | E6: 4
A7: NPOC_CAL | B7: NPOC | C7: 14.19 | D7: 2 | E7: 5
A8: NPOC_CAL | B8: NPOC | C8: 7.179 | D8: 1 | E8: 6
A9: NPOC_CAL | B9: NPOC | C9: 3.66 | D9: 0.5 | E9: 7
A10: NPOC_CAL | B10: NPOC | C10: 0.3301 | D10: 0 | E10: 8
A11: Vial_19 | B11: NPOC | C11: 88.43 | D11: 0 | E11: 19
A12: Vial_20 | B12: NPOC | C12: 56.79 | D12: 0 | E12: 20
A13: Vial_21 | B13: NPOC | C13: 38.2 | D13: 0 | E13: 21
... A74: 0position | B74: NPOC | C74: 0.8876 | D74: 0 | E74: 0

Sheet cal_curves
A1: Complete Calibration Curves | I1: Calibration summary from instrument
A2: NPOC beginning | I2: Analysis | J2: r2 | K2: Standard Error | L2: Intercept | M2: Slope
A3: Sample ID | B3: Mean Area | C3: Prep Conc (g/mL) | I3: NPOC
A4: Blank | B4: =working_data!C10 -> 0.3301 | C4: 0 | I4: TN
A5: Std 1 | B5: =working_data!C4 -> 137.3 | C5: 20
A6: Std 2 | B6: =working_data!C5 -> 69.06 | C6: 10 | I6: NPOC beginning | S6: TN beginning
A7: Std 3 | B7: =working_data!C6 -> 34.2 | C7: 5 | I7: SUMMARY OUTPUT | S7: SUMMARY OUTPUT
A8: Std 4 | B8: =working_data!C7 -> 14.19 | C8: 2
A9: Std 5 | B9: =working_data!C8 -> 7.179 | C9: 1 | I9: Regression Statistics
A10: Std 6 | B10: =working_data!C9 -> 3.66 | C10: 0.5 | I10: Multiple R | J10: 0.99999233
I11: R Square | J11: 0.99998467
I12: Adjusted R Square | J12: 0.9999816
I13: Standard Error | J13: 0.21416301
I14: Observations | J14: 7
I16: ANOVA
J17: df | K17: SS | L17: MS | M17: F | N17: Significance F
I18: Regression | J18: 1 | K18: 14954.53 | L18: 14954.53 | M18: 326049.73 | N18: 3.1266552e-13
I19: Residual | J19: 5 | K19: 0.22932898 | L19: 0.045865797
I20: Total | J20: 6 | K20: 14954.76
J22: Coefficients | K22: Standard Error | L22: t Stat | M22: P-value | N22: Lower 95% | O22: Upper 95% | P22: Lower 95.0% | Q22: Upper 95.0%
I23: Intercept | J23: 0.30120039 | K23: 0.10444342 | L23: 2.8838619 | M23: 0.0344325 | N23: 0.032720042 | O23: 0.56968074 | P23: 0.032720042 | Q23: 0.56968074
I24: Prep Conc (g/mL) | J24: 6.8522259 | K24: 0.012000235 | L24: 571.00764 | M24: 3.1266552e-13 | N24: 6.8213783 | O24: 6.8830735 | P24: 6.8213783 | Q24: 6.8830735
I28: RESIDUAL OUTPUT
I30: Observation | J30: Predicted Mean Area | K30: Residuals | L30: Standard Residuals
I31: 1 | J31: 0.30120039 | K31: 0.028899608 | L31: 0.14782167
I32: 2 | J32: 137.34572 | K32: -0.045718446 | L32: -0.23385013
I33: 3 | J33: 68.823459 | K33: 0.23654058 | L33: 1.2099065
I34: 4 | J34: 34.56233 | K34: -0.36232991 | L34: -1.8533197
I35: 5 | J35: 14.005652 | K35: 0.1843478 | L35: 0.94294012
I36: 6 | J36: 7.1534263 | K36: 0.025573705 | L36: 0.13080966
I37: 7 | J37: 3.7273133 | K37: -0.067313344 | L37: -0.34430816
T129: Predicted Mean Area | U129: Residuals | V129: Standard Residuals
T130: -2.9341104 | U130: 2.9341104 | V130: 0.40251451
T131: 263.6162 | U131: 5.7838037 | V131: 0.7934483
T132: 130.34104 | U132: -12.741043 | V132: -1.7478738
T133: 50.375951 | U133: 1.8440491 | V133: 0.25297498
T134: 23.72092 | U134: 2.1790798 | V134: 0.298936

Sheet calc_data
A1: NPOC (non-purgeable organic carbon) | I1: Final values
A2: Sample Vial | B2: Sample | C2: Mean Area | D2: Conc (mg/L) | E2: Matrix Spike | F2: (Spiked - Unspiked) (hoping for Column E) | G2: % Recovery (hoping for 1) | J2: Conc (mg/L) | K2: Matrix Spike | L2: (Spiked - Unspiked) | M2: % Correct from expected
A3: =working_data!A11 -> Vial_19 | B3: =calculations!B21 -> SLOC 10 mg/L matrix spike | C3: =working_data!C11 -> 88.43 | D3: =(C3-cal_curves!$J$23)/cal_curves!$J$24 -> 12.861339 | E3: 10 | F3: =D3-$D$8 -> 9.4290528 | G3: =F3/E3 -> 0.94290528 | I3: SLOC 10 mg/L matrix spike | J3: 12.861339 | K3: 10 | L3: =J3-$D$8 -> 9.4290528 | M3: =L3/K3 -> 0.94290528
A4: =working_data!A12 -> Vial_20 | B4: =calculations!B22 -> SLOC 5 mg/L matrix spike | C4: =working_data!C12 -> 56.79 | D4: =(C4-cal_curves!$J$23)/cal_curves!$J$24 -> 8.2438613 | E4: 5 | F4: =D4-$D$8 -> 4.8115752 | G4: =F4/E4 -> 0.96231503 | I4: SLOC 5 mg/L matrix spike | J4: 8.2438613 | K4: 5 | L4: =J4-$D$8 -> 4.8115752 | M4: =L4/K4 -> 0.96231503
A5: =working_data!A13 -> Vial_21 | B5: =calculations!B23 -> SLOC 2 mg/L matrix spike | C5: =working_data!C13 -> 38.2 | D5: =(C5-cal_curves!$J$23)/cal_curves!$J$24 -> 5.5308742 | E5: 2 | F5: =D5-$D$8 -> 2.0985881 | G5: =F5/E5 -> 1.0492941 | I5: SLOC 2 mg/L matrix spike | J5: 5.5308742 | K5: 2 | L5: =J5-$D$8 -> 2.0985881 | M5: =L5/K5 -> 1.0492941
A6: =working_data!A14 -> Vial_22 | B6: =calculations!B24 -> SLOC 1 mg/L matrix spike | C6: =working_data!C14 -> 30.55 | D6: =(C6-cal_curves!$J$23)/cal_curves!$J$24 -> 4.4144487 | E6: 1 | F6: =D6-$D$8 -> 0.9821626 | G6: =F6/E6 -> 0.9821626 | I6: SLOC 1 mg/L matrix spike | J6: 4.4144487 | K6: 1 | L6: =J6-$D$8 -> 0.9821626 | M6: =L6/K6 -> 0.9821626
A7: =working_data!A15 -> Vial_23 | B7: =calculations!B25 -> SLOC 0.5 mg/L matrix spike | C7: =working_data!C15 -> 28.28 | D7: =(C7-cal_curves!$J$23)/cal_curves!$J$24 -> 4.0831695 | E7: 0.5 | F7: =D7-$D$8 -> 0.65088339 | G7: =F7/E7 -> 1.3017668 | I7: SLOC 0.5 mg/L matrix spike | J7: 4.0831695 | K7: 0.5 | L7: =J7-$D$8 -> 0.65088339 | M7: =L7/K7 -> 1.3017668
A8: =working_data!A16 -> Vial_24 | B8: =calculations!B26 -> SLOC plain matrix | C8: =working_data!C16 -> 23.82 | D8: =(C8-cal_curves!$J$23)/cal_curves!$J$24 -> 3.4322861 | E8: 0 | I8: SLOC plain matrix | J8: 3.4322861 | K8: 0
A9: =working_data!A17 -> Vial_9_QC1 | C9: =working_data!C17 -> 69.55 | D9: =(C9-cal_curves!$J$23)/cal_curves!$J$24 -> 10.10603 | I9: SLOW 10 mg/L matrix spike | J9: 11.922958 | K9: 10 | L9: =J9-$D$18 -> 9.9573483 | M9: =L9/K9 -> 0.99573483
A10: =working_data!A18 -> Vial_14_blank1 | C10: =working_data!C18 -> 0.5861 | D10: =(C10-cal_curves!$J$23)/cal_curves!$J$24 -> 0.041577673 | I10: SLOW 5 mg/L matrix spike | J10: 6.9435539 | K10: 5 | L10: =J10-$D$18 -> 4.9779445 | M10: =L10/K10 -> 0.99558889
A11: =working_data!A19 -> Vial_43_SLOC_0_REP | C11: =working_data!C19 -> 22.76 | D11: =(C11-cal_curves!$J$23)/cal_curves!$J$24 -> 3.2775918 | E11: 0 | I11: SLOW 2 mg/L matrix spike | J11: 4.1021414 | K11: 2 | L11: =J11-$D$18 -> 2.136532 | M11: =L11/K11 -> 1.068266
A12: =working_data!A20 -> Vial_44_SLOC_10_REP | C12: =working_data!C20 -> 91.35 | D12: =(C12-cal_curves!$J$23)/cal_curves!$J$24 -> 13.287478 | E12: 10 | I12: SLOW 1 mg/L matrix spike | J12: 2.9871752 | K12: 1 | L12: =J12-$D$18 -> 1.0215659 | M12: =L12/K12 -> 1.0215659
A13: =working_data!A21 -> Vial_25 | B13: =calculations!B27 -> SLOW 10 mg/L matrix spike | C13: =working_data!C21 -> 82 | D13: =(C13-cal_curves!$J$23)/cal_curves!$J$24 -> 11.922958 | E13: 10 | F13: =D13-$D$18 -> 9.9573483 | G13: =F13/E13 -> 0.99573483 | I13: SLOW 0.5 mg/L matrix spike | J13: 2.4209359 | K13: 0.5 | L13: =J13-$D$18 -> 0.45532649 | M13: =L13/K13 -> 0.91065299
A14: =working_data!A22 -> Vial_26 | B14: =calculations!B28 -> SLOW 5 mg/L matrix spike | C14: =working_data!C22 -> 47.88 | D14: =(C14-cal_curves!$J$23)/cal_curves!$J$24 -> 6.9435539 | E14: 5 | F14: =D14-$D$18 -> 4.9779445 | G14: =F14/E14 -> 0.99558889 | I14: SLOW plain matrix | J14: 1.9656094 | K14: 0
A15: =working_data!A23 -> Vial_27 | B15: =calculations!B29 -> SLOW 2 mg/L matrix spike | C15: =working_data!C23 -> 28.41 | D15: =(C15-cal_curves!$J$23)/cal_curves!$J$24 -> 4.1021414 | E15: 2 | F15: =D15-$D$18 -> 2.136532 | G15: =F15/E15 -> 1.068266 | I15: VDOS 10 mg/L matrix spike | J15: 14.768748 | K15: 10 | L15: =J15-$D$28 -> 9.8829199 | M15: =L15/K15 -> 0.98829199
A16: =working_data!A24 -> Vial_28 | B16: =calculations!B30 -> SLOW 1 mg/L matrix spike | C16: =working_data!C24 -> 20.77 | D16: =(C16-cal_curves!$J$23)/cal_curves!$J$24 -> 2.9871752 | E16: 1 | F16: =D16-$D$18 -> 1.0215659 | G16: =F16/E16 -> 1.0215659 | I16: VDOS 5 mg/L matrix spike | J16: 9.7105379 | K16: 5 | L16: =J16-$D$28 -> 4.8247096 | M16: =L16/K16 -> 0.96494192
A17: =working_data!A25 -> Vial_29 | B17: =calculations!B31 -> SLOW 0.5 mg/L matrix spike | C17: =working_data!C25 -> 16.89 | D17: =(C17-cal_curves!$J$23)/cal_curves!$J$24 -> 2.4209359 | E17: 0.5 | F17: =D17-$D$18 -> 0.45532649 | G17: =F17/E17 -> 0.91065299 | I17: VDOS 2 mg/L matrix spike | J17: 6.7815627 | K17: 2 | L17: =J17-$D$28 -> 1.8957343 | M17: =L17/K17 -> 0.94786717
A18: =working_data!A26 -> Vial_30 | B18: =calculations!B32 -> SLOW plain matrix | C18: =working_data!C26 -> 13.77 | D18: =(C18-cal_curves!$J$23)/cal_curves!$J$24 -> 1.9656094 | E18: 0 | I18: VDOS 1 mg/L matrix spike | J18: 5.8461003 | K18: 1 | L18: =J18-$D$28 -> 0.9602719 | M18: =L18/K18 -> 0.9602719
A19: =working_data!A27 -> Vial_10_QC2 | C19: =working_data!C27 -> 71.44 | D19: =(C19-cal_curves!$J$23)/cal_curves!$J$24 -> 10.381853 | I19: VDOS 0.5 mg/L matrix spike | J19: 5.2915359 | K19: 0.5 | L19: =J19-$D$28 -> 0.40570758 | M19: =L19/K19 -> 0.81141516
A20: =working_data!A28 -> Vial_15_blank2 | C20: =working_data!C28 -> 0.4273 | D20: =(C20-cal_curves!$J$23)/cal_curves!$J$24 -> 0.018402722 | I20: VDOS plain matrix | J20: 4.8858284 | K20: 0
A21: =working_data!A29 -> Vial_45_SLOW_0_REP | C21: =working_data!C29 -> 12.7 | D21: =(C21-cal_curves!$J$23)/cal_curves!$J$24 -> 1.8094558 | E21: 0 | I21: VDOW 10 mg/L matrix spike | J21: 13.910633 | K21: 10 | L21: =J21-$D$38 -> 9.4669967 | M21: =L21/K21 -> 0.94669967
A22: =working_data!A30 -> Vial_46_SLOW_10_REP | C22: =working_data!C30 -> 80.74 | D22: =(C22-cal_curves!$J$23)/cal_curves!$J$24 -> 11.739076 | E22: 10 | I22: VDOW 5 mg/L matrix spike | J22: 9.2741834 | K22: 5 | L22: =J22-$D$38 -> 4.8305471 | M22: =L22/K22 -> 0.96610942
A23: =working_data!A31 -> Vial_31 | B23: =calculations!B33 -> VDOS 10 mg/L matrix spike | C23: =working_data!C31 -> 101.5 | D23: =(C23-cal_curves!$J$23)/cal_curves!$J$24 -> 14.768748 | E23: 10 | F23: =D23-$D$28 -> 9.8829199 | G23: =F23/E23 -> 0.98829199 | I23: VDOW 2 mg/L matrix spike | J23: 6.4429866 | K23: 2 | L23: =J23-$D$38 -> 1.9993503 | M23: =L23/K23 -> 0.99967516
A24: =working_data!A32 -> Vial_32 | B24: =calculations!B34 -> VDOS 5 mg/L matrix spike | C24: =working_data!C32 -> 66.84 | D24: =(C24-cal_curves!$J$23)/cal_curves!$J$24 -> 9.7105379 | E24: 5 | F24: =D24-$D$28 -> 4.8247096 | G24: =F24/E24 -> 0.96494192 | I24: VDOW 1 mg/L matrix spike | J24: 5.5717369 | K24: 1 | L24: =J24-$D$38 -> 1.1281006 | M24: =L24/K24 -> 1.1281006
A25: =working_data!A33 -> Vial_33 | B25: =calculations!B35 -> VDOS 2 mg/L matrix spike | C25: =working_data!C33 -> 46.77 | D25: =(C25-cal_curves!$J$23)/cal_curves!$J$24 -> 6.7815627 | E25: 2 | F25: =D25-$D$28 -> 1.8957343 | G25: =F25/E25 -> 0.94786717 | I25: VDOW 0.5 mg/L matrix spike | J25: 4.9865256 | K25: 0.5 | L25: =J25-$D$38 -> 0.54288928 | M25: =L25/K25 -> 1.0857786
A26: =working_data!A34 -> Vial_34 | B26: =calculations!B36 -> VDOS 1 mg/L matrix spike | C26: =working_data!C34 -> 40.36 | D26: =(C26-cal_curves!$J$23)/cal_curves!$J$24 -> 5.8461003 | E26: 1 | F26: =D26-$D$28 -> 0.9602719 | G26: =F26/E26 -> 0.9602719 | I26: VDOW plain matrix | J26: 4.4436363 | K26: 0
A27: =working_data!A35 -> Vial_35 | B27: =calculations!B37 -> VDOS 0.5 mg/L matrix spike | C27: =working_data!C35 -> 36.56 | D27: =(C27-cal_curves!$J$23)/cal_curves!$J$24 -> 5.2915359 | E27: 0.5 | F27: =D27-$D$28 -> 0.40570758 | G27: =F27/E27 -> 0.81141516
A28: =working_data!A36 -> Vial_36 | B28: =calculations!B38 -> VDOS plain matrix | C28: =working_data!C36 -> 33.78 | D28: =(C28-cal_curves!$J$23)/cal_curves!$J$24 -> 4.8858284 | E28: 0
A29: =working_data!A37 -> Vial_11_QC3 | C29: =working_data!C37 -> 71.33 | D29: =(C29-cal_curves!$J$23)/cal_curves!$J$24 -> 10.365799
A30: =working_data!A38 -> Vial_16_blank3 | C30: =working_data!C38 -> 0.6499 | D30: =(C30-cal_curves!$J$23)/cal_curves!$J$24 -> 0.050888516
A31: =working_data!A39 -> Vial_47_VDOS_0_REP | C31: =working_data!C39 -> 31.76 | D31: =(C31-cal_curves!$J$23)/cal_curves!$J$24 -> 4.5910336 | E31: 0
A32: =working_data!A40 -> Vial_48_VDOS_10_REP | C32: =working_data!C40 -> 100.4 | D32: =(C32-cal_curves!$J$23)/cal_curves!$J$24 -> 14.608217 | E32: 10
A33: =working_data!A41 -> Vial_37 | B33: =calculations!B39 -> VDOW 10 mg/L matrix spike | C33: =working_data!C41 -> 95.62 | D33: =(C33-cal_curves!$J$23)/cal_curves!$J$24 -> 13.910633 | E33: 10 | F33: =D33-$D$38 -> 9.4669967 | G33: =F33/E33 -> 0.94669967
A34: =working_data!A42 -> Vial_38 | B34: =calculations!B40 -> VDOW 5 mg/L matrix spike | C34: =working_data!C42 -> 63.85 | D34: =(C34-cal_curves!$J$23)/cal_curves!$J$24 -> 9.2741834 | E34: 5 | F34: =D34-$D$38 -> 4.8305471 | G34: =F34/E34 -> 0.96610942
A35: =working_data!A43 -> Vial_39 | B35: =calculations!B41 -> VDOW 2 mg/L matrix spike | C35: =working_data!C43 -> 44.45 | D35: =(C35-cal_curves!$J$23)/cal_curves!$J$24 -> 6.4429866 | E35: 2 | F35: =D35-$D$38 -> 1.9993503 | G35: =F35/E35 -> 0.99967516
A36: =working_data!A44 -> Vial_40 | B36: =calculations!B42 -> VDOW 1 mg/L matrix spike | C36: =working_data!C44 -> 38.48 | D36: =(C36-cal_curves!$J$23)/cal_curves!$J$24 -> 5.5717369 | E36: 1 | F36: =D36-$D$38 -> 1.1281006 | G36: =F36/E36 -> 1.1281006
A37: =working_data!A45 -> Vial_41 | B37: =calculations!B43 -> VDOW 0.5 mg/L matrix spike | C37: =working_data!C45 -> 34.47 | D37: =(C37-cal_curves!$J$23)/cal_curves!$J$24 -> 4.9865256 | E37: 0.5 | F37: =D37-$D$38 -> 0.54288928 | G37: =F37/E37 -> 1.0857786
A38: =working_data!A46 -> Vial_42 | B38: =calculations!B44 -> VDOW plain matrix | C38: =working_data!C46 -> 30.75 | D38: =(C38-cal_curves!$J$23)/cal_curves!$J$24 -> 4.4436363 | E38: 0
A39: =working_data!A47 -> Vial_12_QC4 | C39: =working_data!C47 -> 71.41 | D39: =(C39-cal_curves!$J$23)/cal_curves!$J$24 -> 10.377475
A40: =working_data!A48 -> Vial_17_blank4 | C40: =working_data!C48 -> 0.5535 | D40: =(C40-cal_curves!$J$23)/cal_curves!$J$24 -> 0.036820095
...

Sheet qc_rep_blanks
A1: NPOC QC
A2: Prepared Concentration = | D2: 10 | E2: mg/L
A3: QC # | B3: Mean Area | C3: Measured Conc. | D3: Error | E3: Error Avg
A4: QC 1 | B4: =calc_data!C9 -> 69.55 | C4: =calc_data!D9 -> 10.10603 | D4: =(C4-$D$2)/$D$2 -> 0.010602986 | E4: =AVERAGE(D4:D8) -> 0.03459519
A5: QC 2 | B5: =calc_data!C19 -> 71.44 | C5: =calc_data!D19 -> 10.381853 | D5: =(C5-$D$2)/$D$2 -> 0.038185264
A6: QC 3 | B6: =calc_data!C29 -> 71.33 | C6: =calc_data!D29 -> 10.365799 | D6: =(C6-$D$2)/$D$2 -> 0.036579947
A7: QC 4 | B7: =calc_data!C39 -> 71.41 | C7: =calc_data!D39 -> 10.377475 | D7: =(C7-$D$2)/$D$2 -> 0.037747451
A8: QC 5 | B8: =calc_data!C64 -> 72.24 | C8: =calc_data!D64 -> 10.498603 | D8: =(C8-$D$2)/$D$2 -> 0.049860303
A11: Replicates (Different Vial)
A12: Sample Name | B12: Sample ID | C12: NPOC | D12: NPOC Avg | E12: NPOC % Errors
A13: =calculations!B45 -> SLOC plain matrix | B13: =calc_data!A8 -> Vial_24 | C13: =calc_data!D8 -> 3.4322861 | D13: =AVERAGE(C13:C14) -> 3.354939 | E13: =(C13-C14)/C13 -> 0.045070327
B14: =calc_data!A11 -> Vial_43_SLOC_0_REP | C14: =calc_data!D11 -> 3.2775918
A15: =calculations!B46 -> SLOC 10 mg/L matrix spike | B15: =calc_data!A3 -> Vial_19 | C15: =calc_data!D3 -> 12.861339 | D15: =AVERAGE(C15:C16) -> 13.074408 | E15: =(C15-C16)/C15 -> -0.033133323
B16: =calc_data!A12 -> Vial_44_SLOC_10_REP | C16: =calc_data!D12 -> 13.287478
A17: =calculations!B47 -> SLOW plain matrix | B17: =calc_data!A18 -> Vial_30 | C17: =calc_data!D18 -> 1.9656094 | D17: =AVERAGE(C17:C18) -> 1.8875326 | E17: =(C17-C18)/C17 -> 0.079442863
B18: =calc_data!A21 -> Vial_45_SLOW_0_REP | C18: =calc_data!D21 -> 1.8094558
A19: =calculations!B48 -> SLOW 10 mg/L matrix spike | B19: =calc_data!A13 -> Vial_25 | C19: =calc_data!D13 -> 11.922958 | D19: =AVERAGE(C19:C20) -> 11.831017 | E19: =(C19-C20)/C19 -> 0.015422503
B20: =calc_data!A22 -> Vial_46_SLOW_10_REP | C20: =calc_data!D22 -> 11.739076
A21: =calculations!B49 -> VDOS plain matrix | B21: =calc_data!A28 -> Vial_36 | C21: =calc_data!D28 -> 4.8858284 | D21: =AVERAGE(C21:C22) -> 4.738431 | E21: =(C21-C22)/C21 -> 0.060336691
B22: =calc_data!A31 -> Vial_47_VDOS_0_REP | C22: =calc_data!D31 -> 4.5910336
A23: =calculations!B50 -> VDOS 10 mg/L matrix spike | B23: =calc_data!A23 -> Vial_31 | C23: =calc_data!D23 -> 14.768748 | D23: =AVERAGE(C23:C24) -> 14.688482 | E23: =(C23-C24)/C23 -> 0.010869694
B24: =calc_data!A32 -> Vial_48_VDOS_10_REP | C24: =calc_data!D32 -> 14.608217
A25: =calculations!B51 -> VDOW plain matrix | B25: =calc_data!A38 -> Vial_42 | C25: =calc_data!D38 -> 4.4436363 | D25: =AVERAGE(C25:C26) -> 4.3611813 | E25: =(C25-C26)/C25 -> 0.037111479
B26: =calc_data!A41 -> Vial_49_VDOW_0_REP | C26: =calc_data!D41 -> 4.2787264
A27: =calculations!B52 -> VDOW 10 mg/L matrix spike | B27: =calc_data!A33 -> Vial_37 | C27: =calc_data!D33 -> 13.910633 | D27: =AVERAGE(C27:C28) -> 14.033951 | E27: =(C27-C28)/C27 -> -0.017729976
B28: =calc_data!A42 -> Vial_50_VDOW_10_REP | C28: =calc_data!D42 -> 14.157268
A31: Blanks
A32: Blank # | B32: Mean Area | C32: Conc (mg/L)
B33: NPOC | C33: NPOC
A34: =calc_data!A10 -> Vial_14_blank1 | B34: =calc_data!C10 -> 0.5861 | C34: =(B34-cal_curves!$J$23)/cal_curves!$J$24 -> 0.041577673
A35: =calc_data!A20 -> Vial_15_blank2 | B35: =calc_data!C20 -> 0.4273 | C35: =(B35-cal_curves!$J$23)/cal_curves!$J$24 -> 0.018402722
A36: =calc_data!A30 -> Vial_16_blank3 | B36: =calc_data!C30 -> 0.6499 | C36: =(B36-cal_curves!$J$23)/cal_curves!$J$24 -> 0.050888516
A37: =calc_data!A40 -> Vial_17_blank4 | B37: =calc_data!C40 -> 0.5535 | C37: =(B37-cal_curves!$J$23)/cal_curves!$J$24 -> 0.036820095
A38: =calc_data!A65 -> Vial_18_blank5 | B38: =calc_data!C65 -> 0.3891 | C38: =(B38-cal_curves!$J$23)/cal_curves!$J$24 -> 0.012827891

Sheet calculations
A1: Vial | G1: Cal Curve Standard (NPOC/TN) | I1: NPOC Stock Mass | K1: QC | N1: NPOC mass
A2: # | B2: Sample Name | C2: Info | D2: Sample mL | E2: Dilution mL | F2: Total mL | G2: Stock Conc (ppm) | H2: 1000 | K2: Stock Conc (ppm) | L2: 1000 | M2: QC 1 | N2: 0.2462
A3: 1 | B3: nanopure flush | G3: Vol Flask Final (mL) | H3: 100 | K3: Vol Flask Final (mL) | L3: 25 | M3: QC 2 | N3: 0.2513
A4: 2 | B4: 20 mg/L NPOC | G4: NPOC Desired Conc (mg/L) | H4: 20 | K4: NPOC Desired Conc (mg/L) | L4: 10 | M4: QC 3 | N4: 0.2517
A5: 3 | B5: 10 mg/L NPOC | M5: QC 3 | N5: 0.2523
A6: 4 | B6: 5 mg/L NPOC | G6: NPOC Vol Needed (mL) | H6: =(H4*H3)/H2 -> 2 | I6: 1.9464 | K6: NPOC Vol Needed (mL) | L6: =(L4*L3)/L2 -> 0.25 | M6: QC 5 | N6: 0.2514
A7: 5 | B7: 2 mg/L NPOC
A8: 6 | B8: 1 mg/L NPOC
A9: 7 | B9: 0.5 mg/L NPOC | G9: Stock Conc (ppm) | H9: 1000
A10: 8 | B10: nanopure | G10: Vol Flask Final (mL) | H10: 100
A11: 9 | B11: QC 1 (10 mg-C/L) | G11: NPOC Desired Conc (mg/L) | H11: 10
A12: 10 | B12: QC 2 (10 mg-C/L)
A13: 11 | B13: QC 3 (10 mg-C/L) | G13: NPOC Vol Needed (mL) | H13: =(H11*H10)/H9 -> 1 | I13: 0.9767
A14: 12 | B14: QC 4 (10 mg-C/L)
A15: 13 | B15: QC 5 (10 mg-C/L)
A16: 14 | B16: blank 1 (nanopure) | G16: Stock Conc (ppm) | H16: 1000
A17: 15 | B17: blank 2 (nanopure) | G17: Vol Flask Final (mL) | H17: 100
A18: 16 | B18: blank 3 (nanopure) | G18: NPOC Desired Conc (mg/L) | H18: 5
A19: 17 | B19: blank 4 (nanopure)
A20: 18 | B20: blank 5 (nanopure) | G20: NPOC Vol Needed (mL) | H20: =(H18*H17)/H16 -> 0.5 | I20: 0.4898
A21: 19 | B21: SLOC 10 mg/L matrix spike | C21: filter 2
A22: 20 | B22: SLOC 5 mg/L matrix spike | C22: filter 2
A23: 21 | B23: SLOC 2 mg/L matrix spike | C23: filter 2 | D23: rinsed with 50 mL plain SLOC | G23: Stock Conc (ppm) | H23: 1000
A24: 22 | B24: SLOC 1 mg/L matrix spike | C24: filter 1 | G24: Vol Flask Final (mL) | H24: 100
A25: 23 | B25: SLOC 0.5 mg/L matrix spike | C25: filter 1 | G25: NPOC Desired Conc (mg/L) | H25: 2
A26: 24 | B26: SLOC plain matrix | C26: filter 1
A27: 25 | B27: SLOW 10 mg/L matrix spike | C27: filter 4 | G27: NPOC Vol Needed (mL) | H27: =(H25*H24)/H23 -> 0.2 | I27: 0.195
A28: 26 | B28: SLOW 5 mg/L matrix spike | C28: filter 4
A29: 27 | B29: SLOW 2 mg/L matrix spike | C29: filter 4 | D29: rinsed with 50 mL plain SLOW
A30: 28 | B30: SLOW 1 mg/L matrix spike | C30: filter 3 | G30: Stock Conc (ppm) | H30: 1000
A31: 29 | B31: SLOW 0.5 mg/L matrix spike | C31: filter 3 | G31: Vol Flask Final (mL) | H31: 100
A32: 30 | B32: SLOW plain matrix | C32: filter 3 | G32: NPOC Desired Conc (mg/L) | H32: 1
A33: 31 | B33: VDOS 10 mg/L matrix spike | C33: filter 6
A34: 32 | B34: VDOS 5 mg/L matrix spike | C34: filter 6 | G34: NPOC Vol Needed (mL) | H34: =(H32*H31)/H30 -> 0.1 | I34: 0.0956
A35: 33 | B35: VDOS 2 mg/L matrix spike | C35: filter 6 | D35: rinsed with 50 mL plain VDOS
A36: 34 | B36: VDOS 1 mg/L matrix spike | C36: filter 5
A37: 35 | B37: VDOS 0.5 mg/L matrix spike | C37: filter 5 | G37: Stock Conc (ppm) | H37: 1000
A38: 36 | B38: VDOS plain matrix | C38: filter 5 | G38: Vol Flask Final (mL) | H38: 100
A39: 37 | B39: VDOW 10 mg/L matrix spike | C39: filter 8 | G39: NPOC Desired Conc (mg/L) | H39: 0.5
A40: 38 | B40: VDOW 5 mg/L matrix spike | C40: filter 8
...

Sheet data_report
A1: Sample_ID | B1: NPOC_mg_L | C1: TN_mg_L
A2: SLOC 10 mg/L matrix spike | B2: 12.861339
A3: SLOC 5 mg/L matrix spike | B3: 8.2438613
A4: SLOC 2 mg/L matrix spike | B4: 5.5308742
A5: SLOC 1 mg/L matrix spike | B5: 4.4144487
A6: SLOC 0.5 mg/L matrix spike | B6: 4.0831695
A7: SLOC plain matrix | B7: 3.4322861
A8: SLOW 10 mg/L matrix spike | B8: 11.922958
A9: SLOW 5 mg/L matrix spike | B9: 6.9435539
A10: SLOW 2 mg/L matrix spike | B10: 4.1021414
A11: SLOW 1 mg/L matrix spike | B11: 2.9871752
A12: SLOW 0.5 mg/L matrix spike | B12: 2.4209359
A13: SLOW plain matrix | B13: 1.9656094
... A45: filter test: sample 20 | B45: 0.42640153
